===== Application Startup at 2024-04-09 06:15:02 =====

No changes detected
Operations to perform:
  Apply all migrations: account, admin, auth, contenttypes, main, sessions, socialaccount
Running migrations:
  Applying contenttypes.0001_initial... OK
  Applying auth.0001_initial... OK
  Applying account.0001_initial... OK
  Applying account.0002_email_max_length... OK
  Applying account.0003_alter_emailaddress_create_unique_verified_email... OK
  Applying account.0004_alter_emailaddress_drop_unique_email... OK
  Applying account.0005_emailaddress_idx_upper_email... OK
  Applying admin.0001_initial... OK
  Applying admin.0002_logentry_remove_auto_add... OK
  Applying admin.0003_logentry_add_action_flag_choices... OK
  Applying contenttypes.0002_remove_content_type_name... OK
  Applying auth.0002_alter_permission_name_max_length... OK
  Applying auth.0003_alter_user_email_max_length... OK
  Applying auth.0004_alter_user_username_opts... OK
  Applying auth.0005_alter_user_last_login_null... OK
  Applying auth.0006_require_contenttypes_0002... OK
  Applying auth.0007_alter_validators_add_error_messages... OK
  Applying auth.0008_alter_user_username_max_length... OK
  Applying auth.0009_alter_user_last_name_max_length... OK
  Applying auth.0010_alter_group_name_max_length... OK
  Applying auth.0011_update_proxy_permissions... OK
  Applying auth.0012_alter_user_first_name_max_length... OK
  Applying main.0001_initial... OK
  Applying main.0002_alter_price_timestamp... OK
  Applying main.0003_remove_product_user_alter_product_url_track... OK
  Applying sessions.0001_initial... OK
  Applying socialaccount.0001_initial... OK
  Applying socialaccount.0002_token_max_lengths... OK
  Applying socialaccount.0003_extra_data_default_dict... OK
  Applying socialaccount.0004_app_provider_id_settings... OK
  Applying socialaccount.0005_socialtoken_nullable_app... OK
  Applying socialaccount.0006_alter_socialaccount_extra_data... OK
Watching for file changes with StatReloader
[09/Apr/2024 11:45:22] "GET /?logs=container HTTP/1.1" 302 0
[09/Apr/2024 11:45:22] "GET /?logs=container HTTP/1.1" 302 0
[09/Apr/2024 11:45:22] "GET /accounts/google/login/ HTTP/1.1" 200 684
[09/Apr/2024 11:45:24] "GET /add/ HTTP/1.1" 302 0
[09/Apr/2024 11:45:25] "GET /?next=/add/ HTTP/1.1" 302 0
[09/Apr/2024 11:45:25] "GET /accounts/google/login HTTP/1.1" 301 0
[09/Apr/2024 11:45:25] "GET /accounts/google/login/ HTTP/1.1" 200 684
[09/Apr/2024 11:45:28] "POST /accounts/google/login/ HTTP/1.1" 302 0
[09/Apr/2024 11:45:28] "GET / HTTP/1.1" 302 0
[09/Apr/2024 11:45:28] "GET /accounts/google/login/ HTTP/1.1" 200 684
[09/Apr/2024 11:45:29] "GET /static/main/styles.css HTTP/1.1" 200 3560
[09/Apr/2024 11:45:31] "POST /accounts/google/login/ HTTP/1.1" 302 0
[09/Apr/2024 11:45:32] "GET /accounts/google/login/callback/?state=jsk8pUsb2FEKsOpR&code=4%2F0AeaYSHD0V_jgczJwlgpbzKl6gAIzJcsux_1GT1pW1EdNAY_ZdGqVcWVhbTX350LkEBjRKw&scope=email+profile+openid+https%3A%2F%2Fwww.googleapis.com%2Fauth%2Fuserinfo.profile+https%3A%2F%2Fwww.googleapis.com%2Fauth%2Fuserinfo.email&authuser=0&prompt=none HTTP/1.1" 302 0
[09/Apr/2024 11:45:32] "GET /accounts/google/login/callback/?state=X9OqcpJbZx4fBTzx&code=4%2F0AeaYSHAnEVT4iaWC4qEn9se1Pp3_udm8eZag1JNBvSx-ta_PMYOHpFg0Z_yq7dS0OrEDfg&scope=email+profile+openid+https%3A%2F%2Fwww.googleapis.com%2Fauth%2Fuserinfo.email+https%3A%2F%2Fwww.googleapis.com%2Fauth%2Fuserinfo.profile&authuser=0&prompt=none HTTP/1.1" 302 0
[09/Apr/2024 11:45:32] "GET /add/ HTTP/1.1" 200 1440
[09/Apr/2024 11:45:33] "GET /add/ HTTP/1.1" 200 1440
[09/Apr/2024 11:45:33] "GET /static/main/styles.css HTTP/1.1" 304 0
Internal Server Error: /add/
Traceback (most recent call last):
  File "/usr/local/lib/python3.11/site-packages/django/core/handlers/exception.py", line 55, in inner
    response = get_response(request)
               ^^^^^^^^^^^^^^^^^^^^^
  File "/usr/local/lib/python3.11/site-packages/django/core/handlers/base.py", line 197, in _get_response
    response = wrapped_callback(request, *callback_args, **callback_kwargs)
               ^^^^^^^^^^^^^^^^^^^^^^^^^^^^^^^^^^^^^^^^^^^^^^^^^^^^^^^^^^^^
  File "/usr/local/lib/python3.11/site-packages/django/contrib/auth/decorators.py", line 23, in _wrapper_view
    return view_func(request, *args, **kwargs)
           ^^^^^^^^^^^^^^^^^^^^^^^^^^^^^^^^^^^
  File "/app/main/views.py", line 61, in add_product
    driver = getDriver()
             ^^^^^^^^^^^
  File "/app/scraper/scraper.py", line 38, in getDriver
    driver = webdriver.Chrome(options=getOptions())
             ^^^^^^^^^^^^^^^^^^^^^^^^^^^^^^^^^^^^^^
  File "/usr/local/lib/python3.11/site-packages/selenium/webdriver/chrome/webdriver.py", line 45, in __init__
    super().__init__(
  File "/usr/local/lib/python3.11/site-packages/selenium/webdriver/chromium/webdriver.py", line 61, in __init__
    super().__init__(command_executor=executor, options=options)
  File "/usr/local/lib/python3.11/site-packages/selenium/webdriver/remote/webdriver.py", line 208, in __init__
    self.start_session(capabilities)
  File "/usr/local/lib/python3.11/site-packages/selenium/webdriver/remote/webdriver.py", line 292, in start_session
    response = self.execute(Command.NEW_SESSION, caps)["value"]
               ^^^^^^^^^^^^^^^^^^^^^^^^^^^^^^^^^^^^^^^
  File "/usr/local/lib/python3.11/site-packages/selenium/webdriver/remote/webdriver.py", line 347, in execute
    self.error_handler.check_response(response)
  File "/usr/local/lib/python3.11/site-packages/selenium/webdriver/remote/errorhandler.py", line 229, in check_response
    raise exception_class(message, screen, stacktrace)
selenium.common.exceptions.SessionNotCreatedException: Message: session not created: Chrome failed to start: exited normally.
  (session not created: DevToolsActivePort file doesn't exist)
  (The process started from chrome location /home/webdriver/.cache/selenium/chrome/linux64/123.0.6312.105/chrome is no longer running, so ChromeDriver is assuming that Chrome has crashed.)

[09/Apr/2024 11:45:46] "POST /add/ HTTP/1.1" 500 118275
Internal Server Error: /add/
Traceback (most recent call last):
  File "/usr/local/lib/python3.11/site-packages/django/core/handlers/exception.py", line 55, in inner
    response = get_response(request)
               ^^^^^^^^^^^^^^^^^^^^^
  File "/usr/local/lib/python3.11/site-packages/django/core/handlers/base.py", line 197, in _get_response
    response = wrapped_callback(request, *callback_args, **callback_kwargs)
               ^^^^^^^^^^^^^^^^^^^^^^^^^^^^^^^^^^^^^^^^^^^^^^^^^^^^^^^^^^^^
  File "/usr/local/lib/python3.11/site-packages/django/contrib/auth/decorators.py", line 23, in _wrapper_view
    return view_func(request, *args, **kwargs)
           ^^^^^^^^^^^^^^^^^^^^^^^^^^^^^^^^^^^
  File "/app/main/views.py", line 61, in add_product
    driver = getDriver()
             ^^^^^^^^^^^
  File "/app/scraper/scraper.py", line 38, in getDriver
    driver = webdriver.Chrome(options=getOptions())
             ^^^^^^^^^^^^^^^^^^^^^^^^^^^^^^^^^^^^^^
  File "/usr/local/lib/python3.11/site-packages/selenium/webdriver/chrome/webdriver.py", line 45, in __init__
    super().__init__(
  File "/usr/local/lib/python3.11/site-packages/selenium/webdriver/chromium/webdriver.py", line 61, in __init__
    super().__init__(command_executor=executor, options=options)
  File "/usr/local/lib/python3.11/site-packages/selenium/webdriver/remote/webdriver.py", line 208, in __init__
    self.start_session(capabilities)
  File "/usr/local/lib/python3.11/site-packages/selenium/webdriver/remote/webdriver.py", line 292, in start_session
    response = self.execute(Command.NEW_SESSION, caps)["value"]
               ^^^^^^^^^^^^^^^^^^^^^^^^^^^^^^^^^^^^^^^
  File "/usr/local/lib/python3.11/site-packages/selenium/webdriver/remote/webdriver.py", line 347, in execute
    self.error_handler.check_response(response)
  File "/usr/local/lib/python3.11/site-packages/selenium/webdriver/remote/errorhandler.py", line 229, in check_response
    raise exception_class(message, screen, stacktrace)
selenium.common.exceptions.SessionNotCreatedException: Message: session not created: Chrome failed to start: exited normally.
  (session not created: DevToolsActivePort file doesn't exist)
  (The process started from chrome location /home/webdriver/.cache/selenium/chrome/linux64/123.0.6312.105/chrome is no longer running, so ChromeDriver is assuming that Chrome has crashed.)

[09/Apr/2024 11:45:46] "POST /add/ HTTP/1.1" 500 119560